<?xml version="1.0" ?>
<!-- =================================================================================== -->
<!-- |    This document was autogenerated by xacro from /home/kdy/doosan_ws/src/doosan_mini_project_cpp/models/robot_arm/xacro/e0509.urdf.xacro | -->
<!-- |    EDITING THIS FILE BY HAND IS NOT RECOMMENDED                                 | -->
<!-- =================================================================================== -->
<robot name="e0509">
  <material name="black">
    <color rgba="0.0 0.0 0.0 1.0"/>
  </material>
  <material name="white">
    <color rgba="1.0 1.0 1.0 1.0"/>
  </material>
  <!-- <material name="orange">
    <color rgba="1.0 0.4 0.0 1.0"/>
  </material> -->
  <material name="dr_gray">
    <color rgba="0.490 0.490 0.486 1.0"/>
  </material>
  <material name="dr_white">
    <color rgba="0.941 0.941 0.941 1.0"/>
  </material>
  <material name="dr_blue">
    <color rgba="0 0 0.15 1"/>
  </material>
  <!-- <material name="grey">
    <color rgba="0.5 0.5 0.5 1.0"/>
  </material> -->
  <material name="Boxer_DarkGrey">
    <color rgba="0.3 0.3 0.3 1.0"/>
  </material>
  <material name="blue">
    <color rgba="0.0 0.0 0.8 1.0"/>
  </material>
  <material name="green">
    <color rgba="0.0 0.8 0.0 1.0"/>
  </material>
  <material name="grey">
    <color rgba="0.2 0.2 0.2 1.0"/>
  </material>
  <material name="orange">
    <color rgba="1.0 0.4235294117647059 0.0392156862745098 1.0"/>
  </material>
  <material name="brown">
    <color rgba="0.8705882352941177 0.8117647058823529 0.7647058823529411 1.0"/>
  </material>
  <material name="red">
    <color rgba="0.8 0.0 0.0 1.0"/>
  </material>







  <link name="base_link">
    <inertial>
      <mass value="1.803"/>
      <origin xyz="2.7e-05   -0.002651    0.035122"/>
      <inertia ixx="0.010608" ixy="1.7706e-06" ixz="6.6982e-06" iyy="0.0092656" iyz="-4.7833e-05" izz="0.0092125"/>
    </inertial>
    <collision>
      <origin rpy="0 0 0" xyz="0 0 0"/>
      <geometry>
        <mesh filename="package://doosan_mini_project_cpp/models/robot_arm/meshes/collision/E0509_0_0.dae" scale="0.001 0.001 0.001"/>
      </geometry>
      <material name="dr_white"/>
    </collision>
    <visual>
      <origin rpy="0 0 0" xyz="0 0 0"/>
      <geometry>
        <mesh filename="package://doosan_mini_project_cpp/models/robot_arm/meshes/visual/E0509_0_0.dae" scale="0.001 0.001 0.001"/>
      </geometry>
      <material name="dr_white"/>
    </visual>
  </link>
  <!-- joint 1 -->
  <joint name="joint_1" type="revolute">
    <parent link="base_link"/>
    <child link="link_1"/>
    <origin rpy="0 0 0" xyz="0 0 0.2045"/>
    <axis xyz="0 0 1"/>
    <limit effort="194" lower="-6.2832" upper="6.2832" velocity="3.1416"/>
    <dynamics friction="0"/>
  </joint>

  <link name="link_1">
    <inertial>
      <mass value="5.75"/>
      <origin xyz="1e-06    0.049633   -0.049635"/>
      <inertia ixx="0.046214" ixy="1.4982e-05" ixz="1.281e-05" iyy="0.032573" iyz="-0.013997" izz="0.030999"/>
    </inertial>
    <collision>
      <origin rpy="0 0 0" xyz="0 0 0"/>
      <geometry>
        <mesh filename="package://doosan_mini_project_cpp/models/robot_arm/meshes/collision/E0509_1_1.dae" scale="0.001 0.001 0.001"/>
      </geometry>
      <material name="dr_white"/>
    </collision>
    <visual>
      <origin rpy="0 0 0" xyz="0 0 0"/>
      <geometry>
        <mesh filename="package://doosan_mini_project_cpp/models/robot_arm/meshes/visual/E0509_1_1.dae" scale="0.001 0.001 0.001"/>
      </geometry>
      <material name="dr_white"/>
    </visual>
    <collision>
      <origin rpy="0 0 0" xyz="0 0 0"/>
      <geometry>
        <mesh filename="package://doosan_mini_project_cpp/models/robot_arm/meshes/collision/E0509_1_2.dae" scale="0.001 0.001 0.001"/>
      </geometry>
      <material name="dr_white"/>
    </collision>
    <visual>
      <origin rpy="0 0 0" xyz="0 0 0"/>
      <geometry>
        <mesh filename="package://doosan_mini_project_cpp/models/robot_arm/meshes/visual/E0509_1_2.dae" scale="0.001 0.001 0.001"/>
      </geometry>
      <material name="dr_white"/>
    </visual>
    <collision>
      <origin rpy="0 0 0" xyz="0 0 0"/>
      <geometry>
        <mesh filename="package://doosan_mini_project_cpp/models/robot_arm/meshes/collision/E0509_1_3.dae" scale="0.001 0.001 0.001"/>
      </geometry>
      <material name="dr_white"/>
    </collision>
    <visual>
      <origin rpy="0 0 0" xyz="0 0 0"/>
      <geometry>
        <mesh filename="package://doosan_mini_project_cpp/models/robot_arm/meshes/visual/E0509_1_3.dae" scale="0.001 0.001 0.001"/>
      </geometry>
      <material name="dr_white"/>
    </visual>
    <collision>
      <origin rpy="0 0 0" xyz="0 0 0"/>
      <geometry>
        <mesh filename="package://doosan_mini_project_cpp/models/robot_arm/meshes/collision/E0509_1_4.dae" scale="0.001 0.001 0.001"/>
      </geometry>
      <material name="dr_white"/>
    </collision>
    <visual>
      <origin rpy="0 0 0" xyz="0 0 0"/>
      <geometry>
        <mesh filename="package://doosan_mini_project_cpp/models/robot_arm/meshes/visual/E0509_1_4.dae" scale="0.001 0.001 0.001"/>
      </geometry>
      <material name="dr_white"/>
    </visual>
  </link>

  <!-- joint2 -->
  <joint name="joint_2" type="revolute">
    <parent link="link_1"/>
    <child link="link_2"/>
    <origin rpy="0 -1.5708 -1.5708" xyz="0 0 0"/>
    <axis xyz="0 0 1"/>
    <limit effort="194" lower="-6.2832" upper="6.2832" velocity="3.1416"/>
    <dynamics friction="0"/>
  </joint>

  <link name="link_2">
    <inertial>
      <mass value="3.461"/>
      <origin xyz="0.18647 -1.1418e-17     0.17311"/>
      <inertia ixx="0.012039" ixy="7.7771e-06" ixz="3.7559e-06" iyy="0.091203" iyz="3.1825e-06" izz="0.094721"/>
    </inertial>
    <collision>
      <origin rpy="0 0 0" xyz="0 0 0"/>
      <geometry>
        <mesh filename="package://doosan_mini_project_cpp/models/robot_arm/meshes/collision/E0509_2_1.dae" scale="0.001 0.001 0.001"/>
      </geometry>
      <material name="dr_white"/>
    </collision>
    <visual>
      <origin rpy="0 0 0" xyz="0 0 0"/>
      <geometry>
        <mesh filename="package://doosan_mini_project_cpp/models/robot_arm/meshes/visual/E0509_2_1.dae" scale="0.001 0.001 0.001"/>
      </geometry>
      <material name="dr_white"/>
    </visual>
    <collision>
      <origin rpy="0 0 0" xyz="0 0 0"/>
      <geometry>
        <mesh filename="package://doosan_mini_project_cpp/models/robot_arm/meshes/collision/E0509_2_2.dae" scale="0.001 0.001 0.001"/>
      </geometry>
      <material name="dr_white"/>
    </collision>
    <visual>
      <origin rpy="0 0 0" xyz="0 0 0"/>
      <geometry>
        <mesh filename="package://doosan_mini_project_cpp/models/robot_arm/meshes/visual/E0509_2_2.dae" scale="0.001 0.001 0.001"/>
      </geometry>
      <material name="dr_white"/>
    </visual>
  </link>

  <!-- joint3 -->
  <joint name="joint_3" type="revolute">
    <parent link="link_2"/>
    <child link="link_3"/>
    <origin rpy="0 0 1.5708" xyz="0.373 0 0"/>
    <axis xyz="0 0 1"/>
    <limit effort="194" lower="-2.7053" upper="2.7053" velocity="3.1416"/>
    <dynamics friction="0"/>
  </joint>

  <link name="link_3">
    <inertial>
      <mass value="4.582"/>
      <origin xyz="1.2e-05    -0.02919    0.062355"/>
      <inertia ixx="0.032606" ixy="6.548e-06" ixz="-6.9939e-07" iyy="0.024211" iyz="-0.0079929" izz="0.019284"/>
    </inertial>
    <collision>
      <origin rpy="0 0 0" xyz="0 0 0"/>
      <geometry>
        <mesh filename="package://doosan_mini_project_cpp/models/robot_arm/meshes/collision/E0509_3_1.dae" scale="0.001 0.001 0.001"/>
      </geometry>
      <material name="dr_white"/>
    </collision>
    <visual>
      <origin rpy="0 0 0" xyz="0 0 0"/>
      <geometry>
        <mesh filename="package://doosan_mini_project_cpp/models/robot_arm/meshes/visual/E0509_3_1.dae" scale="0.001 0.001 0.001"/>
      </geometry>
      <material name="dr_white"/>
    </visual>
    <collision>
      <origin rpy="0 0 0" xyz="0 0 0"/>
      <geometry>
        <mesh filename="package://doosan_mini_project_cpp/models/robot_arm/meshes/collision/E0509_3_2.dae" scale="0.001 0.001 0.001"/>
      </geometry>
      <material name="dr_white"/>
    </collision>
    <visual>
      <origin rpy="0 0 0" xyz="0 0 0"/>
      <geometry>
        <mesh filename="package://doosan_mini_project_cpp/models/robot_arm/meshes/visual/E0509_3_2.dae" scale="0.001 0.001 0.001"/>
      </geometry>
      <material name="dr_white"/>
    </visual>
  </link>

  <!-- joint4 -->
  <joint name="joint_4" type="revolute">
    <parent link="link_3"/>
    <child link="link_4"/>
    <origin rpy="1.5708 0 0" xyz="0 -0.373 0"/>
    <axis xyz="0 0 1"/>
    <limit effort="66" lower="-6.2832" upper="6.2832" velocity="3.927"/>
    <dynamics friction="0"/>
  </joint>

  <link name="link_4">
    <inertial>
      <mass value="2.207"/>
      <origin xyz="4e-06    0.095573    -0.12813"/>
      <inertia ixx="0.03547" ixy="8.0794e-06" ixz="7.9905e-06" iyy="0.030841" iyz="-0.011996" izz="0.019615"/>
    </inertial>
    <collision>
      <origin rpy="0 0 0" xyz="0 0 0"/>
      <geometry>
        <mesh filename="package://doosan_mini_project_cpp/models/robot_arm/meshes/collision/E0509_4_1.dae" scale="0.001 0.001 0.001"/>
      </geometry>
      <material name="dr_white"/>
    </collision>
    <visual>
      <origin rpy="0 0 0" xyz="0 0 0"/>
      <geometry>
        <mesh filename="package://doosan_mini_project_cpp/models/robot_arm/meshes/visual/E0509_4_1.dae" scale="0.001 0.001 0.001"/>
      </geometry>
      <material name="dr_white"/>
    </visual>
    <collision>
      <origin rpy="0 0 0" xyz="0 0 0"/>
      <geometry>
        <mesh filename="package://doosan_mini_project_cpp/models/robot_arm/meshes/collision/E0509_4_2.dae" scale="0.001 0.001 0.001"/>
      </geometry>
      <material name="dr_white"/>
    </collision>
    <visual>
      <origin rpy="0 0 0" xyz="0 0 0"/>
      <geometry>
        <mesh filename="package://doosan_mini_project_cpp/models/robot_arm/meshes/visual/E0509_4_2.dae" scale="0.001 0.001 0.001"/>
      </geometry>
      <material name="dr_white"/>
    </visual>
  </link>

  <!-- joint5 -->
  <joint name="joint_5" type="revolute">
    <parent link="link_4"/>
    <child link="link_5"/>
    <origin rpy="-1.5708 0 0" xyz="0 0 0"/>
    <axis xyz="0 0 1"/>
    <limit effort="66" lower="-6.2832" upper="6.2832" velocity="3.927"/>
    <dynamics friction="0"/>
  </joint>

  <link name="link_5">
    <inertial>
      <mass value="3.545"/>
      <origin xyz="-3e-06 -0.038009 0.043841"/>
      <inertia ixx="0.023526" ixy="9.9368e-06" ixz="7.6673e-06" iyy="0.018415" iyz="-0.0059939" izz="0.014249"/>
    </inertial>
    <collision>
      <origin rpy="0 0 0" xyz="0 0 0"/>
      <geometry>
        <mesh filename="package://doosan_mini_project_cpp/models/robot_arm/meshes/collision/E0509_5_1.dae" scale="0.001 0.001 0.001"/>
      </geometry>
      <material name="dr_white"/>
    </collision>
    <visual>
      <origin rpy="0 0 0" xyz="0 0 0"/>
      <geometry>
        <mesh filename="package://doosan_mini_project_cpp/models/robot_arm/meshes/visual/E0509_5_1.dae" scale="0.001 0.001 0.001"/>
      </geometry>
      <material name="dr_white"/>
    </visual>
    <collision>
      <origin rpy="0 0 0" xyz="0 0 0"/>
      <geometry>
        <mesh filename="package://doosan_mini_project_cpp/models/robot_arm/meshes/collision/E0509_5_2.dae" scale="0.001 0.001 0.001"/>
      </geometry>
      <material name="dr_white"/>
    </collision>
    <visual>
      <origin rpy="0 0 0" xyz="0 0 0"/>
      <geometry>
        <mesh filename="package://doosan_mini_project_cpp/models/robot_arm/meshes/visual/E0509_5_2.dae" scale="0.001 0.001 0.001"/>
      </geometry>
      <material name="dr_white"/>
    </visual>
  </link>

  <!-- joint6 -->
  <joint name="joint_6" type="revolute">
    <parent link="link_5"/>
    <child link="link_6"/>
    <origin rpy="1.5708 0 0" xyz="0 -0.1725 0"/>
    <axis xyz="0 0 1"/>
    <limit effort="66" lower="-6.2832" upper="6.2832" velocity="3.927"/>
    <dynamics friction="0"/>
  </joint>

  <link name="link_6">
    <inertial>
      <mass value="0.721"/>
      <origin xyz="5.4e-05   -0.000114   -0.032091"/>
      <inertia ixx="0.0048272" ixy="5.6302e-06" ixz="5.5274e-06" iyy="0.0046772" iyz="3.9598e-06" izz="0.0079424"/>
    </inertial>
    <collision>
      <origin rpy="0 0 0" xyz="0 0 0"/>
      <geometry>
        <mesh filename="package://doosan_mini_project_cpp/models/robot_arm/meshes/collision/E0509_6_1.dae" scale="0.001 0.001 0.001"/>
      </geometry>
      <material name="dr_white"/>
    </collision>
    <visual>
      <origin rpy="0 0 0" xyz="0 0 0"/>
      <geometry>
        <mesh filename="package://doosan_mini_project_cpp/models/robot_arm/meshes/visual/E0509_6_1.dae" scale="0.001 0.001 0.001"/>
      </geometry>
      <material name="dr_white"/>
    </visual>
  </link>

  <!-- Transmission 1 -->
  <transmission name="tran1">
    <type>transmission_interface/SimpleTransmission</type>
    <joint name="joint1">
      <hardwareInterface>hardware_interface/PositionJointInterface</hardwareInterface>
    </joint>
    <actuator name="motor1">
      <mechanicalReduction>1</mechanicalReduction>
    </actuator>
  </transmission>

  <!-- Transmission 2 -->
  <transmission name="tran2">
    <type>transmission_interface/SimpleTransmission</type>
    <joint name="joint2">
      <hardwareInterface>hardware_interface/PositionJointInterface</hardwareInterface>
    </joint>
    <actuator name="motor2">
      <mechanicalReduction>1</mechanicalReduction>
    </actuator>
  </transmission>

  <!-- Transmission 3 -->
  <transmission name="tran3">
    <type>transmission_interface/SimpleTransmission</type>
    <joint name="joint3">
      <hardwareInterface>hardware_interface/PositionJointInterface</hardwareInterface>
    </joint>
    <actuator name="motor3">
      <mechanicalReduction>1</mechanicalReduction>
    </actuator>
  </transmission>

  <!-- Transmission 4 -->
  <transmission name="tran4">
    <type>transmission_interface/SimpleTransmission</type>
    <joint name="joint4">
      <hardwareInterface>hardware_interface/PositionJointInterface</hardwareInterface>
    </joint>
    <actuator name="motor4">
      <mechanicalReduction>1</mechanicalReduction>
    </actuator>
  </transmission>

  <!-- Transmission 5 -->
  <transmission name="tran5">
    <type>transmission_interface/SimpleTransmission</type>
    <joint name="joint5">
      <hardwareInterface>hardware_interface/PositionJointInterface</hardwareInterface>
    </joint>
    <actuator name="motor5">
      <mechanicalReduction>1</mechanicalReduction>
    </actuator>
  </transmission>

  <!-- Transmission 6 -->
  <transmission name="tran6">
    <type>transmission_interface/SimpleTransmission</type>
    <joint name="joint6">
      <hardwareInterface>hardware_interface/PositionJointInterface</hardwareInterface>
    </joint>
    <actuator name="motor6">
      <mechanicalReduction>1</mechanicalReduction>
    </actuator>
  </transmission>

  <!-- ros_control plugin -->
  <gazebo>
    <plugin filename="gz_ros2_control-system" name="gz_ros2_control::GazeboSimROS2ControlPlugin">
      <ros>
        <namespace></namespace>
      </ros>
      <parameters>/home/kdy/doosan_ws/install/dsr_controller2/share/dsr_controller2/config/dsr_controller2_gz.yaml</parameters>
    </plugin>
  </gazebo>

  <!-- Base -->
  <gazebo reference="base_0">
    <kp>100000.0</kp>
    <kd>100.0</kd>
    <mu1>30.0</mu1>
    <mu2>30.0</mu2>
    <maxVel>1.0</maxVel>
    <minDepth>0.001</minDepth>
  </gazebo>

  <!-- Link1 -->
  <gazebo reference="link1">
    <kp>100000.0</kp>
    <kd>100.0</kd>
    <mu1>30.0</mu1>
    <mu2>30.0</mu2>
    <maxVel>1.0</maxVel>
    <minDepth>0.001</minDepth>
  </gazebo>

  <!-- Link2 -->
  <gazebo reference="link2">
    <kp>100000.0</kp>
    <kd>100.0</kd>
    <mu1>30.0</mu1>
    <mu2>30.0</mu2>
    <maxVel>1.0</maxVel>
    <minDepth>0.001</minDepth>
  </gazebo>

  <!-- Link3 -->
  <gazebo reference="link3">
    <kp>100000.0</kp>
    <kd>100.0</kd>
    <mu1>30.0</mu1>
    <mu2>30.0</mu2>
    <maxVel>1.0</maxVel>
    <minDepth>0.001</minDepth>
  </gazebo>

  <!-- Link4 -->
  <gazebo reference="link4">
    <kp>100000.0</kp>
    <kd>100.0</kd>
    <mu1>30.0</mu1>
    <mu2>30.0</mu2>
    <maxVel>1.0</maxVel>
    <minDepth>0.001</minDepth>
  </gazebo>

  <!-- Link5 -->
  <gazebo reference="link5">
    <kp>100000.0</kp>
    <kd>100.0</kd>
    <mu1>30.0</mu1>
    <mu2>30.0</mu2>
    <maxVel>1.0</maxVel>
    <minDepth>0.001</minDepth>
  </gazebo>

  <!-- Link6 -->
  <gazebo reference="link6">
    <kp>100000.0</kp>
    <kd>100.0</kd>
    <mu1>30.0</mu1>
    <mu2>30.0</mu2>
    <maxVel>1.0</maxVel>
    <minDepth>0.001</minDepth>
  </gazebo>

  <!-- World -->
  <link name="world"/>

  <joint name="world_fixed" type="fixed">
    <origin rpy="0 0 0" xyz="0 0 0"/>
    <parent link="world"/>
    <child link="base_link"/>
  </joint>

  <!-- Gazebo -->
  <!-- <xacro:if value="${gz}">
    <xacro:include filename="$(find doosan_mini_project_cpp)/ros2_control/e0509.gz_ros2_control.xacro"/>
    <xacro:e0509_gz_ros2_control 
      namespace="$(arg namespace)"
      update_rate="${update_rate}"
    />
  </xacro:if> -->
  <!-- Default ros2_control -->
  <!-- <xacro:unless value="${gz}">
    <xacro:include filename="$(find doosan_mini_project_cpp)/ros2_control/e0509.ros2_control.xacro" />
    <xacro:e0509_ros2_control
      name="e0509"
      host="${host}"
      rt_host="${rt_host}"
      port="${port}"
      mode="${mode}"
      model="${model}"
      update_rate="${update_rate}"
    />
  </xacro:unless> -->
  <!-- ros_control plugin -->
  <gazebo>
    <plugin filename="libgazebo_ros_control.so" name="gazebo_ros_control">
      <robotNamespace>/rh_p12_rn</robotNamespace>
      <robotSimType>gazebo_ros_control/DefaultRobotHWSim</robotSimType>
      <legacyModeNS>true</legacyModeNS>
    </plugin>
  </gazebo>

  <!-- World -->
  <gazebo reference="world">
  </gazebo>

  <!-- rh_p12_rn_base -->
  <gazebo reference="rh_p12_rn_base">
    <mu1>0.2</mu1>
    <mu2>0.2</mu2>
    <material>Gazebo/Grey</material>
  </gazebo>
  
  <!-- rh_p12_rn_r1 -->
  <gazebo reference="rh_p12_rn_r1">
    <mu1>0.2</mu1>
    <mu2>0.2</mu2>
    <material>Gazebo/Grey</material>
  </gazebo>

  <!-- rh_p12_rn_r2 -->
  <gazebo reference="rh_p12_rn_r2">
    <mu1>0.2</mu1>
    <mu2>0.2</mu2>
    <material>Gazebo/Grey</material>
  </gazebo>

  <!-- rh_p12_rn_l1 -->
  <gazebo reference="rh_p12_rn_l1">
    <mu1>0.2</mu1>
    <mu2>0.2</mu2>
    <material>Gazebo/Grey</material>
  </gazebo>

  <!-- rh_p12_rn_l2 -->
  <gazebo reference="rh_p12_rn_l2">
    <mu1>0.2</mu1>
    <mu2>0.2</mu2>
    <material>Gazebo/Grey</material>
  </gazebo>
  

  <!-- ================== Links ================== -->
  <!-- Used for fixing robot to Gazebo 'link 1' -->
  <!-- <link name="${prefix}world">
    </link> -->
  <!-- base -->
  <link name="rh_p12_rn_base">
    <collision>
      <origin rpy="0 0 0" xyz="0 0 0"/>
      <geometry>
        <mesh filename="package://doosan_mini_project_cpp/models/gripper/meshes/base.stl" scale="0.001 0.001 0.001"/>
      </geometry>
    </collision>
    <visual>
      <origin rpy="0 0 0" xyz="0 0 0"/>
      <geometry>
        <mesh filename="package://doosan_mini_project_cpp/models/gripper/meshes/base.stl" scale="0.001 0.001 0.001"/>
      </geometry>
      <material name="grey"/>
    </visual>
    <inertial>
      <origin rpy="0 0 0" xyz="0.000 0.000 0.032"/>
      <mass value="0.236"/>
      <!--<inertia ixx="0.00017" ixy="0.0" ixz="0.0" iyy="0.00011" iyz="0.0" izz="0.00017" />-->
      <inertia ixx="1.0" ixy="0.0" ixz="0.0" iyy="1.0" iyz="0.0" izz="1.0"/>
    </inertial>
  </link>
  <!-- rh_p12_rn_r1 -->
  <link name="rh_p12_rn_r1">
    <collision>
      <origin rpy="0 0 0" xyz="0 0 0"/>
      <geometry>
        <mesh filename="package://doosan_mini_project_cpp/models/gripper/meshes/r1.stl" scale="0.001 0.001 0.001"/>
      </geometry>
    </collision>
    <visual>
      <origin rpy="0 0 0" xyz="0 0 0"/>
      <geometry>
        <mesh filename="package://doosan_mini_project_cpp/models/gripper/meshes/r1.stl" scale="0.001 0.001 0.001"/>
      </geometry>
      <material name="grey"/>
    </visual>
    <inertial>
      <origin rpy="0 0 0" xyz="0.000 0.034 0.004"/>
      <mass value="0.068"/>
      <!--<inertia ixx="0.00004" ixy="0.0" ixz="0.0" iyy="0.00002" iyz="-0.00001" izz="0.00002" />-->
      <inertia ixx="1.0" ixy="0.0" ixz="0.0" iyy="1.0" iyz="0.0" izz="1.0"/>
    </inertial>
  </link>
  <!-- rh_p12_rn_l1 -->
  <link name="rh_p12_rn_l1">
    <collision>
      <origin rpy="0 0 0" xyz="0 0 0"/>
      <geometry>
        <mesh filename="package://doosan_mini_project_cpp/models/gripper/meshes/l1.stl" scale="0.001 0.001 0.001"/>
      </geometry>
    </collision>
    <visual>
      <origin rpy="0 0 0" xyz="0 0 0"/>
      <geometry>
        <mesh filename="package://doosan_mini_project_cpp/models/gripper/meshes/l1.stl" scale="0.001 0.001 0.001"/>
      </geometry>
      <material name="grey"/>
    </visual>
    <inertial>
      <origin rpy="0 0 0" xyz="0.000 -0.034 0.004"/>
      <mass value="0.068"/>
      <!--<inertia ixx="0.00004" ixy="0.0" ixz="0.0" iyy="0.00002" iyz="0.00001" izz="0.00002" />-->
      <inertia ixx="1.0" ixy="0.0" ixz="0.0" iyy="1.0" iyz="0.0" izz="1.0"/>
    </inertial>
  </link>
  <!-- rh_p12_rn_r2 -->
  <link name="rh_p12_rn_r2">
    <collision>
      <origin rpy="0 0 0" xyz="0 0 0"/>
      <geometry>
        <mesh filename="package://doosan_mini_project_cpp/models/gripper/meshes/r2.stl" scale="0.001 0.001 0.001"/>
      </geometry>
    </collision>
    <visual>
      <origin rpy="0 0 0" xyz="0 0 0"/>
      <geometry>
        <mesh filename="package://doosan_mini_project_cpp/models/gripper/meshes/r2.stl" scale="0.001 0.001 0.001"/>
      </geometry>
      <material name="grey"/>
    </visual>
    <inertial>
      <origin rpy="0 0 0" xyz="0.000 0.006 0.011"/>
      <mass value="0.022"/>
      <!--<inertia ixx="0.0" ixy="0.0" ixz="0.0" iyy="0.00001" iyz="0.0" izz="0.0" />-->
      <inertia ixx="1.0" ixy="0.0" ixz="0.0" iyy="1.0" iyz="0.0" izz="1.0"/>
    </inertial>
  </link>
  <!-- rh_p12_rn_l2 -->
  <link name="rh_p12_rn_l2">
    <collision>
      <origin rpy="0 0 0" xyz="0 0 0"/>
      <geometry>
        <mesh filename="package://doosan_mini_project_cpp/models/gripper/meshes/l2.stl" scale="0.001 0.001 0.001"/>
      </geometry>
    </collision>
    <visual>
      <origin rpy="0 0 0" xyz="0 0 0"/>
      <geometry>
        <mesh filename="package://doosan_mini_project_cpp/models/gripper/meshes/l2.stl" scale="0.001 0.001 0.001"/>
      </geometry>
      <material name="grey"/>
    </visual>
    <inertial>
      <origin rpy="0 0 0" xyz="0.000 -0.006 0.011"/>
      <mass value="0.022"/>
      <!--<inertia ixx="0.0" ixy="0.0" ixz="0.0" iyy="0.00001" iyz="0.0" izz="0.0" />-->
      <inertia ixx="1.0" ixy="0.0" ixz="0.0" iyy="1.0" iyz="0.0" izz="1.0"/>
    </inertial>
  </link>
  <!-- ========================================== -->
  <!-- ================== Joints ================== -->
  <joint name="parent_arm_to_base" type="fixed">
    <origin rpy="0 0 0" xyz="0 0 0"/>
    <parent link="link_6"/>
    <child link="rh_p12_rn_base"/>
  </joint>
  <!-- Joint -->
  <joint name="rh_p12_rn" type="revolute">
    <parent link="rh_p12_rn_base"/>
    <child link="rh_p12_rn_r1"/>
    <origin rpy="0 0 0" xyz="0.0 0.008 0.048"/>
    <axis xyz="1 0 0"/>
    <limit effort="1000" lower="0.0" upper="1.1" velocity="6.5"/>
    <dynamics damping="0.7"/>
  </joint>
  <!-- Right Joint 2 -->
  <joint name="rh_r2" type="revolute">
    <parent link="rh_p12_rn_r1"/>
    <child link="rh_p12_rn_r2"/>
    <origin rpy="0 0 0" xyz="0.0 0.0493634 0.0285"/>
    <axis xyz="-1 0 0"/>
    <limit effort="1000" lower="0.0" upper="1.0" velocity="6.5"/>
    <dynamics damping="0.7"/>
  </joint>
  <!-- Left Joint 1 -->
  <joint name="rh_l1" type="revolute">
    <parent link="rh_p12_rn_base"/>
    <child link="rh_p12_rn_l1"/>
    <origin rpy="0 0 0" xyz="0.0 -0.008 0.048"/>
    <axis xyz="-1 0 0"/>
    <limit effort="1000" lower="0.0" upper="1.1" velocity="6.5"/>
    <dynamics damping="0.7"/>
  </joint>
  <!-- Left Joint 2 -->
  <joint name="rh_l2" type="revolute">
    <parent link="rh_p12_rn_l1"/>
    <child link="rh_p12_rn_l2"/>
    <origin rpy="0 0 0" xyz="0.0 -0.0493634 0.0285"/>
    <axis xyz="1 0 0"/>
    <limit effort="1000" lower="0.0" upper="1.0" velocity="6.5"/>
    <dynamics damping="0.7"/>
  </joint>
  <!-- ========================================== -->
  <!-- ================== Transmissions ================== -->
  <transmission name="tran_r1">
    <type>transmission_interface/SimpleTransmission</type>
    <joint name="rh_p12_rn">
      <hardwareInterface>hardware_interface/EffortJointInterface</hardwareInterface>
    </joint>
    <actuator name="motor_r1">
      <hardwareInterface>hardware_interface/EffortJointInterface</hardwareInterface>
      <mechanicalReduction>1</mechanicalReduction>
    </actuator>
  </transmission>
  <transmission name="tran_r2">
    <type>transmission_interface/SimpleTransmission</type>
    <joint name="rh_r2">
      <hardwareInterface>hardware_interface/EffortJointInterface</hardwareInterface>
    </joint>
    <actuator name="motor_r2">
      <hardwareInterface>hardware_interface/EffortJointInterface</hardwareInterface>
      <mechanicalReduction>1</mechanicalReduction>
    </actuator>
  </transmission>
  <transmission name="tran_l1">
    <type>transmission_interface/SimpleTransmission</type>
    <joint name="rh_l1">
      <hardwareInterface>hardware_interface/EffortJointInterface</hardwareInterface>
    </joint>
    <actuator name="motor_l1">
      <hardwareInterface>hardware_interface/EffortJointInterface</hardwareInterface>
      <mechanicalReduction>1</mechanicalReduction>
    </actuator>
  </transmission>
  <transmission name="tran_l2">
    <type>transmission_interface/SimpleTransmission</type>
    <joint name="rh_l2">
      <hardwareInterface>hardware_interface/EffortJointInterface</hardwareInterface>
    </joint>
    <actuator name="motor_l2">
      <hardwareInterface>hardware_interface/EffortJointInterface</hardwareInterface>
      <mechanicalReduction>1</mechanicalReduction>
    </actuator>
  </transmission>
  <!-- ================================================= -->
  <!-- <xacro:include filename="$(find doosan_mini_project_cpp)/models/gripper/xacro/robotis_rh_p12_rn.ros2_control.xacro"/>
      <xacro:robotiq_gripper_system
      mode="$(arg mode)"
      joint_name="$(arg gripper_prefix)robotiq_85_left_knuckle_joint"
      system_name="$(arg gripper_prefix)robotiq_gripper_system"
      pos_min="0.0"
      pos_max="0.8"
      init_pos="0.0"
      speed_mult="1.0"
      force_mult="0.5"
      max_speed="0.150"
      max_force="235.0"
      mock_sensor_commands="true" /> -->
</robot>
